WARNING:tornado.general:error on read
Traceback (most recent call last):
  File "/webapps/mathmap_static/local/lib/python2.7/site-packages/tornado/iostream.py", line 404, in _handle_read
    if self._read_to_buffer() == 0:
  File "/webapps/mathmap_static/local/lib/python2.7/site-packages/tornado/iostream.py", line 460, in _read_to_buffer
    chunk = self.read_from_fd()
  File "/webapps/mathmap_static/local/lib/python2.7/site-packages/tornado/iostream.py", line 696, in read_from_fd
    chunk = self.socket.recv(self.read_chunk_size)
error: [Errno 110] Connection timed out
WARNING:tornado.general:error on read
Traceback (most recent call last):
  File "/webapps/mathmap_static/local/lib/python2.7/site-packages/tornado/iostream.py", line 404, in _handle_read
    if self._read_to_buffer() == 0:
  File "/webapps/mathmap_static/local/lib/python2.7/site-packages/tornado/iostream.py", line 460, in _read_to_buffer
    chunk = self.read_from_fd()
  File "/webapps/mathmap_static/local/lib/python2.7/site-packages/tornado/iostream.py", line 696, in read_from_fd
    chunk = self.socket.recv(self.read_chunk_size)
error: [Errno 110] Connection timed out
WARNING:tornado.access:404 GET http://www.yahoo.com/ (188.95.104.14) 0.45ms
WARNING:tornado.general:error on read
Traceback (most recent call last):
  File "/webapps/mathmap_static/local/lib/python2.7/site-packages/tornado/iostream.py", line 404, in _handle_read
    if self._read_to_buffer() == 0:
  File "/webapps/mathmap_static/local/lib/python2.7/site-packages/tornado/iostream.py", line 460, in _read_to_buffer
    chunk = self.read_from_fd()
  File "/webapps/mathmap_static/local/lib/python2.7/site-packages/tornado/iostream.py", line 696, in read_from_fd
    chunk = self.socket.recv(self.read_chunk_size)
error: [Errno 110] Connection timed out
WARNING:tornado.access:404 GET /w00tw00t.at.ISC.SANS.DFind:) (5.79.65.163) 0.81ms
